<?xml version="1.0" encoding="utf-8"?>
<!-- This URDF was automatically created by SolidWorks to URDF Exporter! Originally created by Stephen Brawner (brawner@gmail.com) 
     Commit Version: 1.6.0-4-g7f85cfe  Build Version: 1.6.7995.38578
     For more information, please see http://wiki.ros.org/sw_urdf_exporter -->
<robot
  name="robot">
  <link
    name="base_link">
    <inertial>
      <origin
        xyz="-0.0236348524240362 0.000475427070029771 0.112188762443571"
        rpy="0 0 0" />
      <mass
        value="10.6449686651718" />
      <inertia
        ixx="0.0737924307811315"
        ixy="0.000550146671427836"
        ixz="-0.000644869704817392"
        iyy="0.0995128660812024"
        iyz="-0.000163368262706657"
        izz="0.0889379695705377" />
    </inertial>
    <visual>
      <origin
        xyz="0 0 0"
        rpy="0 0 0" />
      <geometry>
        <mesh
          filename="package://robot/meshes/base_link.STL" />
      </geometry>
      <material
        name="">
        <color
          rgba="0.784313725490196 0.8 0.788235294117647 1" />
      </material>
    </visual>
    <collision>
      <origin
        xyz="0 0 0"
        rpy="0 0 0" />
      <geometry>
        <mesh
          filename="package://robot/meshes/base_link.STL" />
      </geometry>
    </collision>
  </link>
  <link
    name="link_1">
    <inertial>
      <origin
        xyz="0.00326733568292923 -0.000445650437164745 0.321298198961239"
        rpy="0 0 0" />
      <mass
        value="6.0652883927885" />
      <inertia
        ixx="0.0758224519393498"
        ixy="-2.39216083546777E-05"
        ixz="0.00055965924585347"
        iyy="0.0480670971680946"
        iyz="-9.54875983906173E-05"
        izz="0.0552627698980604" />
    </inertial>
    <visual>
      <origin
        xyz="0 0 0"
        rpy="0 0 0" />
      <geometry>
        <mesh
          filename="package://robot/meshes/link_1.STL" />
      </geometry>
      <material
        name="">
        <color
          rgba="0.792156862745098 0.819607843137255 0.933333333333333 1" />
      </material>
    </visual>
    <collision>
      <origin
        xyz="0 0 0"
        rpy="0 0 0" />
      <geometry>
        <mesh
          filename="package://robot/meshes/link_1.STL" />
      </geometry>
    </collision>
  </link>
  <joint
    name="joint_1"
    type="revolute">
    <origin
      xyz="0 0 0"
      rpy="0 0 0" />
    <parent
      link="base_link" />
    <child
      link="link_1" />
    <axis
      xyz="0 0 1" />
    <limit
      lower="-3.927"
      upper="0.7854"
      effort="24.654"
      velocity="0.0635" />
    <dynamics
      damping="0"
      friction="0" />
  </joint>
  <link
    name="link_2">
    <inertial>
      <origin
        xyz="0.0123330655644807 0.218476553306462 -0.00215876234609192"
        rpy="0 0 0" />
      <mass
        value="7.97368837843458" />
      <inertia
        ixx="0.266964889956692"
        ixy="0.00108088395116057"
        ixz="-5.99370748130455E-05"
        iyy="0.0431959568139251"
        iyz="0.000341659504447131"
        izz="0.244728200586045" />
    </inertial>
    <visual>
      <origin
        xyz="0 0 0"
        rpy="0 0 0" />
      <geometry>
        <mesh
          filename="package://robot/meshes/link_2.STL" />
      </geometry>
      <material
        name="">
        <color
          rgba="0.792156862745098 0.819607843137255 0.933333333333333 1" />
      </material>
    </visual>
    <collision>
      <origin
        xyz="0 0 0"
        rpy="0 0 0" />
      <geometry>
        <mesh
          filename="package://robot/meshes/link_2.STL" />
      </geometry>
    </collision>
  </link>
  <joint
    name="joint_2"
    type="revolute">
    <origin
      xyz="0 0 0.3991"
      rpy="1.5708 0 0" />
    <parent
      link="link_1" />
    <child
      link="link_2" />
    <axis
      xyz="0 0 1" />
    <limit
      lower="-3.927"
      upper="0.7854"
      effort="24.654"
      velocity="0.0635" />
    <dynamics
      damping="0"
      friction="0" />
  </joint>
  <link
    name="link_3">
    <inertial>
      <origin
        xyz="0.0350293794732254 0.0981181437488218 -0.00429559704085071"
        rpy="0 0 0" />
      <mass
        value="6.40139739415592" />
      <inertia
        ixx="0.0720942155648782"
        ixy="-0.00521185050032234"
        ixz="4.3680628328032E-05"
        iyy="0.0203656922106737"
        iyz="0.000123417000470017"
        izz="0.0782976256297945" />
    </inertial>
    <visual>
      <origin
        xyz="0 0 0"
        rpy="0 0 0" />
      <geometry>
        <mesh
          filename="package://robot/meshes/link_3.STL" />
      </geometry>
      <material
        name="">
        <color
          rgba="0.792156862745098 0.819607843137255 0.933333333333333 1" />
      </material>
    </visual>
    <collision>
      <origin
        xyz="0 0 0"
        rpy="0 0 0" />
      <geometry>
        <mesh
          filename="package://robot/meshes/link_3.STL" />
      </geometry>
    </collision>
  </link>
  <joint
    name="joint_3"
    type="revolute">
    <origin
      xyz="0 0.448 0"
      rpy="0 0 1.5708" />
    <parent
      link="link_2" />
    <child
      link="link_3" />
    <axis
      xyz="0 0 -1" />
    <limit
      lower="-3.927"
      upper="0.7854"
      effort="24.654"
      velocity="0.0635" />
    <dynamics
      damping="0"
      friction="0" />
  </joint>
  <link
    name="link_4">
    <inertial>
      <origin
        xyz="-0.00162791756930337 -0.00115265789445296 0.0692515282894517"
        rpy="0 0 0" />
      <mass
        value="1.7965210288116" />
      <inertia
        ixx="0.00735234445649293"
        ixy="-1.26652883817372E-06"
        ixz="0.000175149794736696"
        iyy="0.00789104490559941"
        iyz="-6.0652973277511E-05"
        izz="0.00374689292520669" />
    </inertial>
    <visual>
      <origin
        xyz="0 0 0"
        rpy="0 0 0" />
      <geometry>
        <mesh
          filename="package://robot/meshes/link_4.STL" />
      </geometry>
      <material
        name="">
        <color
          rgba="0.792156862745098 0.819607843137255 0.933333333333333 1" />
      </material>
    </visual>
    <collision>
      <origin
        xyz="0 0 0"
        rpy="0 0 0" />
      <geometry>
        <mesh
          filename="package://robot/meshes/link_4.STL" />
      </geometry>
    </collision>
  </link>
  <joint
    name="joint_4"
    type="revolute">
    <origin
      xyz="0.04154 0.2885 -0.0045003"
      rpy="1.5708 1.5708 0" />
    <parent
      link="link_3" />
    <child
      link="link_4" />
    <axis
      xyz="0 0 -1" />
    <limit
      lower="-3.927"
      upper="0.7854"
      effort="24.654"
      velocity="0.0635" />
    <dynamics
      damping="0"
      friction="0" />
  </joint>
  <link
    name="link_5">
    <inertial>
      <origin
        xyz="5.49143664258511E-05 -0.020848004936838 0.00242847162156216"
        rpy="0 0 0" />
      <mass
        value="0.57863093651427" />
      <inertia
        ixx="0.00099795535516615"
        ixy="-1.44308357104613E-06"
        ixz="5.63593913785332E-07"
        iyy="0.000443157386254628"
        iyz="-2.25900854580162E-05"
        izz="0.00113730967188407" />
    </inertial>
    <visual>
      <origin
        xyz="0 0 0"
        rpy="0 0 0" />
      <geometry>
        <mesh
          filename="package://robot/meshes/link_5.STL" />
      </geometry>
      <material
        name="">
        <color
          rgba="0.780392156862745 0.8 0.788235294117647 1" />
      </material>
    </visual>
    <collision>
      <origin
        xyz="0 0 0"
        rpy="0 0 0" />
      <geometry>
        <mesh
          filename="package://robot/meshes/link_5.STL" />
      </geometry>
    </collision>
  </link>
  <joint
    name="joint_5"
    type="revolute">
    <origin
      xyz="0.0064997 -5.9133E-05 0.161"
      rpy="3.1416 1.5708 0" />
    <parent
      link="link_4" />
    <child
      link="link_5" />
    <axis
      xyz="0 0 -1" />
    <limit
      lower="-3.927"
      upper="0.7854"
      effort="24.654"
      velocity="0.0635" />
    <dynamics
      damping="0"
      friction="0" />
  </joint>
</robot>